Workbook

Sheet I_Inputs & Assumptions
A1: CONSTRUCTION-TO-PERMANENT FINANCIAL MODEL
A2: INPUTS & ASSUMPTIONS
A4: PROJECT INFORMATION
A5: Project Name | B5: Campus Adele
A6: Location | B6: Quebec
A7: Construction Start Date | B7: 2025-03-01
A8: Construction Duration | B8: 13 | C8: months
A9: Months Until First Units Ready | B9: 16 | C9: months
A10: Gap to Permanent Financing | B10: 1 | C10: months
A11: Permanent Loan Term | B11: 60 | C11: months
A12: Exit Timing (Post-Construction) | B12: 61 | C12: months
A14: CONSTRUCTION BUDGET
A15: Land - Purchase Price | B15: 400000
A16: Land - Recognized Value | B16: 600000
A17: Assessed Property Value | B17: 15000000
A18: Hard Costs by Category | B18: Budget | C18: Phasing % | D18: Holdback % | E18: Release (mo)
A19: Site Work & Demolition | B19: 500000 | C19: Equal | D19: 0.1 | E19: 3
A20: Foundation & Structure | B20: 3000000 | C20: Front-loaded | D20: 0.1 | E20: 2
A21: Building Envelope | B21: 2000000 | C21: Mid-weighted | D21: 0.1 | E21: 3
A22: MEP Systems | B22: 2500000 | C22: Mid-weighted | D22: 0.1 | E22: 4
A23: Interior Finishes | B23: 1500000 | C23: Back-loaded | D23: 0.1 | E23: 2
A24: Landscaping & Site | B24: 300000 | C24: Back-loaded | D24: 0.1 | E24: 6
A26: Soft Costs by Category | B26: Budget | C26: Holdback %
A27: Architecture & Engineering | B27: 400000 | C27: 0.1
A28: Permits & Approvals | B28: 150000 | C28: 0
A29: Legal & Financing Fees | B29: 200000 | C29: 0
A30: Development Management | B30: 300000 | C30: 0.1
A31: Marketing & Leasing | B31: 100000 | C31: 0
A33: Contingency | B33: 500000
A35: CONSTRUCTION FINANCING - SENIOR LOAN
A36: Loan-to-Cost (LTC) % | B36: 0.7719 | C36: % | G36: ='Sources & Uses - Construction'!A4 -> SOURCES OF FUNDS | H36: ='Sources & Uses - Construction'!B4 -> Amount
A37: Interest Rate (Annual) | B37: 0.0495 | C37: % | G37: ='Sources & Uses - Construction'!A5 -> In disbursement priority order (1→5) | H37: ='Sources & Uses - Construction'!B5 -> 0
A38: Commitment Fee | B38: 0.001 | C38: % | G38: ='Sources & Uses - Construction'!A6 -> 1. Class A Equity (GP - Land Contribution) | H38: ='Sources & Uses - Construction'!B6 -> 15
A39: Loan Amount | B39: 33627000 | C39: % | G39: ='Sources & Uses - Construction'!A7 -> 2. Class E Equity (LP Units) | H39: ='Sources & Uses - Construction'!B7 -> 2800015
A40: SUBORDINATED LOAN #1 - PREFERRED EQUITY | G40: ='Sources & Uses - Construction'!A8 -> 3. Subordinated Loan #1 (Preferred Equity) | H40: ='Sources & Uses - Construction'!B8 -> 0
A41: Loan Amount | B41: 0 | G41: ='Sources & Uses - Construction'!A9 -> 4. Subordinated Loan #2 (Mezzanine) | H41: ='Sources & Uses - Construction'!B9 -> 0
A42: Interest Rate (Annual) | B42: 0.08 | C42: % | G42: ='Sources & Uses - Construction'!A10 -> 0 | H42: ='Sources & Uses - Construction'!B10 -> 0
A43: Commitment Fee | B43: 0.001 | C43: % | G43: ='Sources & Uses - Construction'!A11 -> Required Additional Equity | H43: ='Sources & Uses - Construction'!B11 -> 7137311.9
A44: Draw Priority | B44: 1 | G44: ='Sources & Uses - Construction'!A12 -> 0 | H44: ='Sources & Uses - Construction'!B12 -> 0
G45: ='Sources & Uses - Construction'!A13 -> 5. Senior Construction Loan | H45: ='Sources & Uses - Construction'!B13 -> 33628383
...

Sheet I_Budget Input Data
A1: BUDGET INPUT DATA
A2: Imported from ryanbudget.csv - Edit phasing, holdback, and eligibility as needed
A4: Row # | B4: Category | C4: Subcategory | D4: Budget Amount | E4: Phasing Pattern | F4: Holdback % | G4: Holdback Release (mo after constr) | H4: GST/QST Eligible
A5: 1 | D5: 0 | E5: Equal | F5: 0.1 | G5: 3 | H5: Yes
A6: 2 | B6: 1. LAND | C6: Land Acquisition | D6: 1600000 | E6: Upfront | F6: 0 | G6: 0 | H6: Yes
A7: 3 | B7: 1. LAND | C7: Notary and cadastre | D7: 19808 | E7: Upfront | F7: 0 | G7: 0 | H7: Yes
A8: 4 | B8: 1. LAND | C8: Cadastral operation | D8: 105360 | E8: Upfront | F8: 0 | G8: 0 | H8: Yes
A9: 5 | B9: 2. SITE SERVICING + LANDSCAPE | C9: Extension of services:Excavation & Backfill - Adjustment for Bldgs 5 & 6 | D9: 479320 | E9: Front-loaded | F9: 0.1 | G9: 3 | H9: Yes
A10: 6 | B10: 2. SITE SERVICING + LANDSCAPE | C10: Extension of services:Excavation & Backfill - Trailer pad, Access road, Septic tank | D10: 10900 | E10: Front-loaded | F10: 0.1 | G10: 3 | H10: Yes
A11: 7 | B11: 2. SITE SERVICING + LANDSCAPE | C11: Extension of services:Credit - Reservoir change | D11: 1946765 | E11: Front-loaded | F11: 0.1 | G11: 3 | H11: Yes
A12: 8 | B12: 2. SITE SERVICING + LANDSCAPE | C12: Extension of services:Credit - Reservoir change | D12: 0 | E12: Front-loaded | F12: 0.1 | G12: 3 | H12: Yes
A13: 9 | B13: 2. SITE SERVICING + LANDSCAPE | C13: Extension of services:Excavation & Backfill - Campus Civil | D13: 143113 | E13: Front-loaded | F13: 0.1 | G13: 3 | H13: Yes
A14: 10 | B14: 2. SITE SERVICING + LANDSCAPE | C14: Extension of services:Excavation & Backfill - Campus Civil | D14: 30493 | E14: Front-loaded | F14: 0.1 | G14: 3 | H14: Yes
A15: 11 | B15: 2. SITE SERVICING + LANDSCAPE | C15: Extension of services:Excavation & backfill - Extension - Mtee Ryan Civil | D15: 375295 | E15: Front-loaded | F15: 0.1 | G15: 3 | H15: Yes
A16: 12 | B16: 2. SITE SERVICING + LANDSCAPE | D16: 165563 | E16: Front-loaded | F16: 0.1 | G16: 3 | H16: Yes
A17: 13 | B17: 2. SITE SERVICING + LANDSCAPE | C17: Onsite services - civil:Excavation & Backfill (PC) | D17: 475672 | E17: Front-loaded | F17: 0.1 | G17: 3 | H17: Yes
A18: 14 | B18: 2. SITE SERVICING + LANDSCAPE | C18: Onsite services - civil:Excavation & Backfill (PC) | D18: 23100 | E18: Front-loaded | F18: 0.1 | G18: 3 | H18: Yes
A19: 15 | B19: 2. SITE SERVICING + LANDSCAPE | C19: Onsite services - civil:Excavation & Backfill (PC) | D19: 2300 | E19: Front-loaded | F19: 0.1 | G19: 3 | H19: Yes
A20: 16 | B20: 2. SITE SERVICING + LANDSCAPE | C20: Onsite services - civil:Excavation & Backfill (PC) | D20: 25102 | E20: Front-loaded | F20: 0.1 | G20: 3 | H20: Yes
A21: 17 | B21: 2. SITE SERVICING + LANDSCAPE | C21: Onsite services - civil:Excavation & Backfill (PC) | D21: 47223 | E21: Front-loaded | F21: 0.1 | G21: 3 | H21: Yes
A22: 18 | B22: 2. SITE SERVICING + LANDSCAPE | C22: Landscaping:Excavation & Backfill - Landscaping | D22: 1065794 | E22: Front-loaded | F22: 0.1 | G22: 3 | H22: Yes
A23: 19 | B23: 2. SITE SERVICING + LANDSCAPE | C23: Electrical services | D23: 252500 | E23: Front-loaded | F23: 0.1 | G23: 3 | H23: Yes
A24: 20 | B24: 2. SITE SERVICING + LANDSCAPE | C24: Electrical charging stations | D24: 124981 | E24: Front-loaded | F24: 0.1 | G24: 3 | H24: Yes
A25: 21 | B25: 3. HARD COSTS | C25: Admin and profit | D25: 1577987 | E25: Equal | F25: 0.1 | G25: 3 | H25: Yes
A26: 22 | B26: 3. HARD COSTS | C26: Insurance and bonding:Insurance | D26: 278718 | E26: Equal | F26: 0.1 | G26: 3 | H26: Yes
A27: 23 | B27: 3. HARD COSTS | D27: 140525 | E27: Equal | F27: 0.1 | G27: 3 | H27: Yes
A28: 24 | B28: 3. HARD COSTS | C28: Insurance and bonding:Wrap-up | D28: 36465 | E28: Equal | F28: 0.1 | G28: 3 | H28: Yes
A29: 25 | B29: 3. HARD COSTS | C29: Insurance and bonding:Bris des Machines | D29: 2585 | E29: Equal | F29: 0.1 | G29: 3 | H29: Yes
A30: 26 | B30: 3. HARD COSTS | C30: Insurance and bonding:L&M and Performance Bonds | D30: 0 | E30: Equal | F30: 0.1 | G30: 3 | H30: Yes
A31: 27 | B31: 3. HARD COSTS | C31: General conditions:CoSS Agent | D31: 236000 | E31: Equal | F31: 0.1 | G31: 3 | H31: Yes
A32: 28 | B32: 3. HARD COSTS | C32: General conditions:RSS Agent | D32: 213500 | E32: Equal | F32: 0.1 | G32: 3 | H32: Yes
A33: 29 | B33: 3. HARD COSTS | C33: General conditions:Superintendent 1 | D33: 303400 | E33: Equal | F33: 0.1 | G33: 3 | H33: Yes
A34: 30 | B34: 3. HARD COSTS | C34: General conditions:Superintendent 2 | D34: 266400 | E34: Equal | F34: 0.1 | G34: 3 | H34: Yes
A35: 31 | B35: 3. HARD COSTS | C35: General conditions:Project Manager | D35: 150750 | E35: Equal | F35: 0.1 | G35: 3 | H35: Yes
A36: 32 | B36: 3. HARD COSTS | C36: General conditions:Labourer | D36: 230020 | E36: Equal | F36: 0.1 | G36: 3 | H36: Yes
A37: 33 | B37: 3. HARD COSTS | C37: General Conditions: Logding | D37: 11000 | E37: Equal | F37: 0.1 | G37: 3 | H37: Yes
A38: 34 | B38: 3. HARD COSTS | C38: General conditions:Site fencing | D38: 10780 | E38: Equal | F38: 0.1 | G38: 3 | H38: Yes
A39: 35 | B39: 3. HARD COSTS | C39: General Conditions: Printing | D39: 8048 | E39: Equal | F39: 0.1 | G39: 3 | H39: Yes
... A57: 53 | B57: 3. HARD COSTS | C57: General conditions:Project signage | D57: 181830 | E57: Equal | F57: 0.1 | G57: 3 | H57: Yes
A58: 54 | B58: 3. HARD COSTS | D58: 6000 | E58: Equal | F58: 0.1 | G58: 3 | H58: Yes
...

Sheet I_Unit Rent Roll Data
A1: UNIT RENT ROLL DATA
A2: Exact import from Units-Proforma_View_Tremb.csv
A4: UnitId | B4: UnitRentalTypes | C4: Unit # | D4: Planned Delivery Date for Occupancy | E4: Projected Price Per Bedroom (from UnitRentalTypes) | F4: Projected Rate | G4: Bedroom Count (from UnitRentalTypes) | H4: Units Operations ID
A5: ADELE 1 A-101 | B5: London | C5: 101 | F5: 1905 | H5: ADELE -101 | I5: =F5*G5 -> 0
A6: ADELE 1 A-201 | B6: Berlin | C6: 201 | F6: 2455 | H6: ADELE -201 | I6: =F6*G6 -> 0
A7: ADELE 1 A-301 | B7: Berlin | C7: 301 | F7: 2455 | H7: ADELE -301
A8: ADELE 1 A-102 | B8: London | C8: 102 | F8: 1905 | H8: ADELE -102
A9: ADELE 1 A-202 | B9: Berlin | C9: 202 | F9: 2455 | H9: ADELE -202
A10: ADELE 1 A-302 | B10: Berlin | C10: 302 | F10: 2455 | H10: ADELE -302
A11: ADELE 1 B-101 | B11: London | C11: 101 | F11: 1905 | H11: ADELE -101
A12: ADELE 1 B-201 | B12: Paris | C12: 201 | F12: 1639 | H12: ADELE -201
A13: ADELE 1 B-202 | B13: New York | C13: 202 | F13: 1589 | H13: ADELE -202
A14: ADELE 1 B-301 | B14: Paris | C14: 301 | F14: 1639 | H14: ADELE -301
A15: ADELE 1 B-302 | B15: New York | C15: 302 | F15: 1589 | H15: ADELE -302
A16: ADELE 1 B-102 | B16: London | C16: 102 | F16: 1905 | H16: ADELE -102
A17: ADELE 1 B-202 | B17: Paris | C17: 202 | F17: 1639 | H17: ADELE -202
A18: ADELE 1 B-203 | B18: New York | C18: 203 | F18: 1589 | H18: ADELE -203
... A68: ADELE 3 H-302 | B68: New York | C68: 302 | F68: 1589 | H68: ADELE -302

Sheet i_Cap Table
A1: CAPITALIZATION TABLE
A2: Investor equity commitments and capital calls
A4: INVESTOR COMMITMENTS
A5: Investor Name | B5: Class | C5: Commitment Amount | D5: % of Class | E5: % of Total Equity
A6: Vafkor | B6: E | C6: 750000 | D6: =C6/SUMIF($B$6,"E",$C$6) -> 1 | E6: =C6/SUM($C$6) -> 1
A7: Masteko Inc | B7: E | C7: 500000 | D7: =C7/SUMIF($B$6:$B$7,"E",$C$6:$C$7) -> 0.4 | E7: =C7/SUM($C$6:$C$7) -> 0.4
A8: Gerome | B8: A | C8: 4.5 | D8: =C8/SUMIF($B$6:$B$8,"A",$C$6:$C$8) -> 1 | E8: =C8/SUM($C$6:$C$8) -> 3.599987e-06
A9: Julie Maranda Medicine Professional Corporation | B9: A | C9: 10.5 | D9: =C9/SUMIF($B$6:$B$9,"A",$C$6:$C$9) -> 0.7 | E9: =C9/SUM($C$6:$C$9) -> 8.3998992e-06
A10: Masteko Inc (Additional) | B10: E | C10: 3152 | D10: =C10/SUMIF($B$6:$B$10,"E",$C$6:$C$10) -> 0.0025152575 | E10: =C10/SUM($C$6:$C$10) -> 0.0025152274
A11: Michel Roux Holding Co | B11: E | C11: 250000 | D11: =C11/SUMIF($B$6:$B$11,"E",$C$6:$C$11) -> 0.16631718 | E11: =C11/SUM($C$6:$C$11) -> 0.16631552
A12: Dr Éric Tardif C.P. Inc. | B12: E | C12: 250000 | D12: =C12/SUMIF($B$6:$B$12,"E",$C$6:$C$12) -> 0.1426003 | E12: =C12/SUM($C$6:$C$12) -> 0.14259908
A13: Tristan Koran | B13: E | C13: 100000 | D13: =C13/SUMIF($B$6:$B$13,"E",$C$6:$C$13) -> 0.053962114 | E13: =C13/SUM($C$6:$C$13) -> 0.053961677
A14: Additional Equity Required | B14: E | C14: ='I_Inputs & Assumptions'!B68-SUMIF(B6:B13,"E",C6:C13) -> 946848 | D14: =C14/SUMIF($B$6:$B$14,"E",$C$6:$C$14) -> 0.33816 | E14: =C14/SUM($C$6:$C$14) -> 0.33815819
A15: CLASS A SUBTOTAL (GP - Land Contribution) | B15: A | C15: =SUMIF(B6:B14,"A",C6:C14) -> 15 | D15: 100.00% | E15: =C15/SUM(C6:C14) -> 5.3571142e-06
A16: CLASS E SUBTOTAL (LP Units) | B16: E | C16: =SUMIF(B6:B14,"E",C6:C14) -> 2800000 | D16: 100.00% | E16: =C16/SUM(C6:C14) -> 0.99999464
A18: TOTAL EQUITY COMMITMENTS | C18: =C15+C16 -> 2800015 | E18: 100.00%
A21: CAPITAL CALLS DURING CONSTRUCTION
A22: Based on pro-rata share when Class E equity is called
A24: Investor Name | B24: Class | C24: Commitment | D24: % of Class E | E24: Total Called | F24: Remaining
A25: Vafkor | B25: E | C25: =C6 -> 750000 | D25: =C25/C$16 -> 0.26785714 | E25: =C25 -> 750000 | F25: =C25-E25 -> 0
A26: Masteko Inc | B26: E | C26: =C7 -> 500000 | D26: =C26/C$16 -> 0.17857143 | E26: =C26 -> 500000 | F26: =C26-E26 -> 0
A27: Gerome | B27: A | C27: =C8 -> 4.5 | D27: N/A - Class A | E27: =C27 -> 4.5 | F27: =C27-E27 -> 0
A28: Julie Maranda Medicine Professional Corporation | B28: A | C28: =C9 -> 10.5 | D28: N/A - Class A | E28: =C28 -> 10.5 | F28: =C28-E28 -> 0
A29: Masteko Inc (Additional) | B29: E | C29: =C10 -> 3152 | D29: =C29/C$16 -> 0.0011257143 | E29: =C29 -> 3152 | F29: =C29-E29 -> 0
A30: Michel Roux Holding Co | B30: E | C30: =C11 -> 250000 | D30: =C30/C$16 -> 0.089285714 | E30: =C30 -> 250000 | F30: =C30-E30 -> 0
A31: Dr Éric Tardif C.P. Inc. | B31: E | C31: =C12 -> 250000 | D31: =C31/C$16 -> 0.089285714 | E31: =C31 -> 250000 | F31: =C31-E31 -> 0
A32: Tristan Koran | B32: E | C32: =C13 -> 100000 | D32: =C32/C$16 -> 0.035714286 | E32: =C32 -> 100000 | F32: =C32-E32 -> 0
A33: Additional Equity Required | B33: E | C33: =C14 -> 946848 | D33: =C33/C$16 -> 0.33816 | E33: =C33 -> 946848 | F33: =C33-E33 -> 0
A34: TOTAL CAPITAL CALLED | C34: =SUM(C25:C33) -> 2800015 | E34: =SUM(E25:E33) -> 2800015 | F34: =SUM(F25:F33) -> 0
A37: NOTE: 'Total Called' is now editable (yellow cells)
A38: • By default, Total Called = Commitment | B38: =C18 -> 2800015
A39: • Edit Total Called amounts as capital is actually called | B39: =E34 -> 2800015
A40: • Senior Construction Financing and other tabs reference these values | B40: ='Senior Construction Financing'!B57 -> 2800015
A41: Difference (Should be close to $0) | B41: =B40-B39 -> 0

Sheet I_Preferred Equity
A1: PREFERRED EQUITY TABLE
A2: Subordinated Loan #1 - Preferred Equity investors
A4: PREFERRED EQUITY INVESTORS
A5: ID | B5: Investor Name | C5: Contribution Amount | D5: Interest Rate | E5: Notes
A6: PE1 | C6: 0 | D6: 0
A7: PE2 | C7: 0 | D7: 0
A8: PE3 | C8: 0 | D8: 0
A9: PE4 | C9: 0 | D9: 0
A10: PE5 | C10: 0 | D10: 0
A11: PE6 | B11: =B32-B13-B10*2 -> 0 | C11: 0 | D11: 0
A12: PE7 | C12: 0 | D12: 0
A13: PE8 | C13: 0 | D13: 0
A14: PE9 | C14: 0 | D14: 0
A15: PE10 | C15: 0 | D15: 0
A17: TOTAL | B17: Preferred Equity | C17: =SUM(C6:C15) -> 0 | D17: Weighted Avg: | E17: =SUMPRODUCT(C6:C15,D6:D15)/C17 -> #DIV/0!
A20: INSTRUCTIONS:
A21: • Enter investor names in column B (yellow cells)
A22: • Enter contribution amounts in column C (yellow cells)
A23: • Enter interest rates in column D (yellow cells)
A24: • Add any notes in column E
A25: • Total will update automatically
A26: • This total is linked to Sources & Uses - Construction
B30: =-B13 -> 0
B36: =B16 -> 0
B37: =B32 -> 0
B38: =B36-B37 -> 0

Sheet I_Mezzanine Debt
A1: MEZZANINE DEBT TABLE
A2: Subordinated Loan #2 - Mezzanine lenders
A4: MEZZANINE LENDERS
A5: ID | B5: Lender Name | C5: Loan Amount | D5: Interest Rate | E5: Notes
A6: MEZZ1 | C6: 0 | D6: 0
A7: MEZZ2 | C7: 0 | D7: 0
A8: MEZZ3 | C8: 0 | D8: 0
A9: MEZZ4 | C9: 0 | D9: 0
A10: MEZZ5 | C10: 0 | D10: 0
A11: MEZZ6 | C11: 0 | D11: 0
A12: MEZZ7 | C12: 0 | D12: 0
A13: MEZZ8 | C13: 0 | D13: 0
A14: MEZZ9 | C14: 0 | D14: 0
A15: MEZZ10 | C15: 0 | D15: 0
A17: TOTAL | B17: Mezzanine Debt | C17: =SUM(C6:C15) -> 0 | D17: Weighted Avg: | E17: =SUMPRODUCT(C6:C15,D6:D15)/C17 -> #DIV/0!
A20: INSTRUCTIONS:
A21: • Enter lender names in column B (yellow cells)
A22: • Enter loan amounts in column C (yellow cells)
A23: • Enter interest rates in column D (yellow cells)
A24: • Add any notes in column E
A25: • Total will update automatically
A26: • This total is linked to Sources & Uses - Construction

Sheet Construction Budget & Draws
A1: CONSTRUCTION BUDGET & DRAWS
A2: References Budget Input Data tab
A4: BUDGET SUMMARY BY CATEGORY
A5: 1. LAND | B5: =SUMIF('I_Budget Input Data'!$B:$B,"1. LAND",'I_Budget Input Data'!$D:$D) -> 1725168
A6: 2. SITE SERVICING + LANDSCAPE | B6: =SUMIF('I_Budget Input Data'!$B:$B,"2. SITE SERVICING + LANDSCAPE",'I_Budget Input Data'!$D:$D) -> 5168121
A7: 3. HARD COSTS | B7: =SUMIF('I_Budget Input Data'!$B:$B,"3. HARD COSTS",'I_Budget Input Data'!$D:$D) -> 25732155
A8: 4. FF&E | B8: =SUMIF('I_Budget Input Data'!$B:$B,"4. FF&E",'I_Budget Input Data'!$D:$D) -> 1792768
A9: 5. PROFESSIONAL FEES | B9: =SUMIF('I_Budget Input Data'!$B:$B,"5. PROFESSIONAL FEES",'I_Budget Input Data'!$D:$D) -> 3283546
A10: 6. FINANCE AND ADMINISTRATION | B10: =SUMIF('I_Budget Input Data'!$B:$B,"6. FINANCE AND ADMINISTRATION",'I_Budget Input Data'!$D:$D) -> 3276350
A11: 7. TAX ASSESSMENT | B11: =SUMIF('I_Budget Input Data'!$B:$B,"7. TAX ASSESSMENT",'I_Budget Input Data'!$D:$D) -> 2087617
A12: 8. CONTINGENCY ALLOWANCE | B12: =SUMIF('I_Budget Input Data'!$B:$B,"8. CONTINGENCY ALLOWANCE",'I_Budget Input Data'!$D:$D) -> 500000
A14: TOTAL PROJECT COST (Before Cap Interest) | B14: =SUM(B5:B12) -> 43565725
A15: Capitalized Interest (from Financing tabs) | B15: ='Senior Construction Financing'!B56 -> 0
A16: =B174 -> Construction interest | B16: =-C174 -> -1592483
A17: GRAND TOTAL PROJECT COST | B17: =B14+IF(ISNUMBER(B15),B15,0) -> 43565725
A20: MONTHLY DRAW SCHEDULE
A21: Detailed monthly draws by line item
A22: Phasing logic:
A23: Category | B23: Subcategory | C23: Budget Amount | D23: Planned Budget Amount | E23: Checksum | F23: Month 1 | G23: Month 2 | H23: Month 3 | I23: Month 4 | J23: Month 5 | K23: Month 6 | L23: Month 7 | M23: Month 8 | N23: Month 9 | O23: Month 10 | P23: Month 11 | Q23: Month 12 | R23: Month 13 | S23: Month 14 | T23: Month 15 | U23: Month 16 | V23: Month 17 | W23: Month 18 | X23: Month 19 | Y23: Month 20 | Z23: Month 21 | AA23: Month 22 | AB23: Month 23 | AC23: Month 24 | AD23: Month 25 | AE23: Month 26 | AF23: Month 27 | AG23: Month 28 | AH23: Month 29 | AI23: Month 30 | AJ23: Month 31 | AK23: Month 32 | AL23: Month 33 | AM23: Month 34 | AN23: Month 35 | AO23: Month 36
A24: ='I_Budget Input Data'!B6 -> 1. LAND | B24: ='I_Budget Input Data'!C6 -> Land Acquisition | C24: ='I_Budget Input Data'!D6 -> 1600000 | D24: =SUM(F24:AO24) -> 1600000 | E24: =C24-D24 -> 0 | F24: ='Draw Calc (Hidden)'!C6 -> 1600000 | G24: ='Draw Calc (Hidden)'!D6 -> 0 | H24: ='Draw Calc (Hidden)'!E6 -> 0 | I24: ='Draw Calc (Hidden)'!F6 -> 0 | J24: ='Draw Calc (Hidden)'!G6 -> 0 | K24: ='Draw Calc (Hidden)'!H6 -> 0 | L24: ='Draw Calc (Hidden)'!I6 -> 0 | M24: ='Draw Calc (Hidden)'!J6 -> 0 | ... AO24: ='Draw Calc (Hidden)'!AL6 -> 0
A25: ='I_Budget Input Data'!B7 -> 1. LAND | B25: ='I_Budget Input Data'!C7 -> Notary and cadastre | C25: ='I_Budget Input Data'!D7 -> 19808 | D25: =SUM(F25:AO25) -> 19808 | E25: =C25-D25 -> 0 | F25: ='Draw Calc (Hidden)'!C7 -> 19808 | G25: ='Draw Calc (Hidden)'!D7 -> 0 | H25: ='Draw Calc (Hidden)'!E7 -> 0 | I25: ='Draw Calc (Hidden)'!F7 -> 0 | J25: ='Draw Calc (Hidden)'!G7 -> 0 | K25: ='Draw Calc (Hidden)'!H7 -> 0 | L25: ='Draw Calc (Hidden)'!I7 -> 0 | M25: ='Draw Calc (Hidden)'!J7 -> 0 | ... AO25: ='Draw Calc (Hidden)'!AL7 -> 0
A26: ='I_Budget Input Data'!B8 -> 1. LAND | B26: ='I_Budget Input Data'!C8 -> Cadastral operation | C26: ='I_Budget Input Data'!D8 -> 105360 | D26: =SUM(F26:AO26) -> 105360 | E26: =C26-D26 -> 0 | F26: ='Draw Calc (Hidden)'!C8 -> 105360 | G26: ='Draw Calc (Hidden)'!D8 -> 0 | H26: ='Draw Calc (Hidden)'!E8 -> 0 | I26: ='Draw Calc (Hidden)'!F8 -> 0 | J26: ='Draw Calc (Hidden)'!G8 -> 0 | K26: ='Draw Calc (Hidden)'!H8 -> 0 | L26: ='Draw Calc (Hidden)'!I8 -> 0 | M26: ='Draw Calc (Hidden)'!J8 -> 0 | ... AO26: ='Draw Calc (Hidden)'!AL8 -> 0
A27: ='I_Budget Input Data'!B9 -> 2. SITE SERVICING + LANDSCAPE | B27: ='I_Budget Input Data'!C9 -> Extension of services:Excavation & Backfill - Adjustment for Bldgs 5 & 6 | C27: ='I_Budget Input Data'!D9 -> 479320 | D27: =SUM(F27:AO27) -> 471945.85 | E27: =C27-D27 -> 7374.1538 | F27: ='Draw Calc (Hidden)'!C9 -> 44244.923 | G27: ='Draw Calc (Hidden)'!D9 -> 44244.923 | H27: ='Draw Calc (Hidden)'!E9 -> 44244.923 | I27: ='Draw Calc (Hidden)'!F9 -> 44244.923 | J27: ='Draw Calc (Hidden)'!G9 -> 44244.923 | K27: ='Draw Calc (Hidden)'!H9 -> 44244.923 | L27: ='Draw Calc (Hidden)'!I9 -> 29496.615 | M27: ='Draw Calc (Hidden)'!J9 -> 29496.615 | ... AO27: ='Draw Calc (Hidden)'!AL9 -> 0
A28: ='I_Budget Input Data'!B10 -> 2. SITE SERVICING + LANDSCAPE | B28: ='I_Budget Input Data'!C10 -> Extension of services:Excavation & Backfill - Trailer pad, Access road, Septic tank | C28: ='I_Budget Input Data'!D10 -> 10900 | D28: =SUM(F28:AO28) -> 10732.308 | E28: =C28-D28 -> 167.69231 | F28: ='Draw Calc (Hidden)'!C10 -> 1006.1538 | G28: ='Draw Calc (Hidden)'!D10 -> 1006.1538 | H28: ='Draw Calc (Hidden)'!E10 -> 1006.1538 | I28: ='Draw Calc (Hidden)'!F10 -> 1006.1538 | J28: ='Draw Calc (Hidden)'!G10 -> 1006.1538 | K28: ='Draw Calc (Hidden)'!H10 -> 1006.1538 | L28: ='Draw Calc (Hidden)'!I10 -> 670.76923 | M28: ='Draw Calc (Hidden)'!J10 -> 670.76923 | ... AO28: ='Draw Calc (Hidden)'!AL10 -> 0
A29: ='I_Budget Input Data'!B11 -> 2. SITE SERVICING + LANDSCAPE | B29: ='I_Budget Input Data'!C11 -> Extension of services:Credit - Reservoir change | C29: ='I_Budget Input Data'!D11 -> 1946765 | D29: =SUM(F29:AO29) -> 1916814.8 | E29: =C29-D29 -> 29950.231 | F29: ='Draw Calc (Hidden)'!C11 -> 179701.38 | G29: ='Draw Calc (Hidden)'!D11 -> 179701.38 | H29: ='Draw Calc (Hidden)'!E11 -> 179701.38 | I29: ='Draw Calc (Hidden)'!F11 -> 179701.38 | J29: ='Draw Calc (Hidden)'!G11 -> 179701.38 | K29: ='Draw Calc (Hidden)'!H11 -> 179701.38 | L29: ='Draw Calc (Hidden)'!I11 -> 119800.92 | M29: ='Draw Calc (Hidden)'!J11 -> 119800.92 | ... AO29: ='Draw Calc (Hidden)'!AL11 -> 0
A30: ='I_Budget Input Data'!B12 -> 2. SITE SERVICING + LANDSCAPE | B30: ='I_Budget Input Data'!C12 -> Extension of services:Credit - Reservoir change | C30: ='I_Budget Input Data'!D12 -> 0 | D30: =SUM(F30:AO30) -> 0 | E30: =C30-D30 -> 0 | F30: ='Draw Calc (Hidden)'!C12 -> 0 | G30: ='Draw Calc (Hidden)'!D12 -> 0 | H30: ='Draw Calc (Hidden)'!E12 -> 0 | I30: ='Draw Calc (Hidden)'!F12 -> 0 | J30: ='Draw Calc (Hidden)'!G12 -> 0 | K30: ='Draw Calc (Hidden)'!H12 -> 0 | L30: ='Draw Calc (Hidden)'!I12 -> 0 | M30: ='Draw Calc (Hidden)'!J12 -> 0 | ... AO30: ='Draw Calc (Hidden)'!AL12 -> 0
A31: ='I_Budget Input Data'!B13 -> 2. SITE SERVICING + LANDSCAPE | B31: ='I_Budget Input Data'!C13 -> Extension of services:Excavation & Backfill - Campus Civil | C31: ='I_Budget Input Data'!D13 -> 143113 | D31: =SUM(F31:AO31) -> 140911.26 | E31: =C31-D31 -> 2201.7385 | F31: ='Draw Calc (Hidden)'!C13 -> 13210.431 | G31: ='Draw Calc (Hidden)'!D13 -> 13210.431 | H31: ='Draw Calc (Hidden)'!E13 -> 13210.431 | I31: ='Draw Calc (Hidden)'!F13 -> 13210.431 | J31: ='Draw Calc (Hidden)'!G13 -> 13210.431 | K31: ='Draw Calc (Hidden)'!H13 -> 13210.431 | L31: ='Draw Calc (Hidden)'!I13 -> 8806.9538 | M31: ='Draw Calc (Hidden)'!J13 -> 8806.9538 | ... AO31: ='Draw Calc (Hidden)'!AL13 -> 0
A32: ='I_Budget Input Data'!B14 -> 2. SITE SERVICING + LANDSCAPE | B32: ='I_Budget Input Data'!C14 -> Extension of services:Excavation & Backfill - Campus Civil | C32: ='I_Budget Input Data'!D14 -> 30493 | D32: =SUM(F32:AO32) -> 30023.877 | E32: =C32-D32 -> 469.12308 | F32: ='Draw Calc (Hidden)'!C14 -> 2814.7385 | G32: ='Draw Calc (Hidden)'!D14 -> 2814.7385 | H32: ='Draw Calc (Hidden)'!E14 -> 2814.7385 | I32: ='Draw Calc (Hidden)'!F14 -> 2814.7385 | J32: ='Draw Calc (Hidden)'!G14 -> 2814.7385 | K32: ='Draw Calc (Hidden)'!H14 -> 2814.7385 | L32: ='Draw Calc (Hidden)'!I14 -> 1876.4923 | M32: ='Draw Calc (Hidden)'!J14 -> 1876.4923 | ... AO32: ='Draw Calc (Hidden)'!AL14 -> 0
A33: ='I_Budget Input Data'!B15 -> 2. SITE SERVICING + LANDSCAPE | B33: ='I_Budget Input Data'!C15 -> Extension of services:Excavation & backfill - Extension - Mtee Ryan Civil | C33: ='I_Budget Input Data'!D15 -> 375295 | D33: =SUM(F33:AO33) -> 369521.23 | E33: =C33-D33 -> 5773.7692 | F33: ='Draw Calc (Hidden)'!C15 -> 34642.615 | G33: ='Draw Calc (Hidden)'!D15 -> 34642.615 | H33: ='Draw Calc (Hidden)'!E15 -> 34642.615 | I33: ='Draw Calc (Hidden)'!F15 -> 34642.615 | J33: ='Draw Calc (Hidden)'!G15 -> 34642.615 | K33: ='Draw Calc (Hidden)'!H15 -> 34642.615 | L33: ='Draw Calc (Hidden)'!I15 -> 23095.077 | M33: ='Draw Calc (Hidden)'!J15 -> 23095.077 | ... AO33: ='Draw Calc (Hidden)'!AL15 -> 0
A34: ='I_Budget Input Data'!B16 -> 2. SITE SERVICING + LANDSCAPE | B34: ='I_Budget Input Data'!C16 -> 0 | C34: ='I_Budget Input Data'!D16 -> 165563 | D34: =SUM(F34:AO34) -> 163015.88 | E34: =C34-D34 -> 2547.1231 | F34: ='Draw Calc (Hidden)'!C16 -> 15282.738 | G34: ='Draw Calc (Hidden)'!D16 -> 15282.738 | H34: ='Draw Calc (Hidden)'!E16 -> 15282.738 | I34: ='Draw Calc (Hidden)'!F16 -> 15282.738 | J34: ='Draw Calc (Hidden)'!G16 -> 15282.738 | K34: ='Draw Calc (Hidden)'!H16 -> 15282.738 | L34: ='Draw Calc (Hidden)'!I16 -> 10188.492 | M34: ='Draw Calc (Hidden)'!J16 -> 10188.492 | ... AO34: ='Draw Calc (Hidden)'!AL16 -> 0
A35: ='I_Budget Input Data'!B17 -> 2. SITE SERVICING + LANDSCAPE | B35: ='I_Budget Input Data'!C17 -> Onsite services - civil:Excavation & Backfill (PC) | C35: ='I_Budget Input Data'!D17 -> 475672 | D35: =SUM(F35:AO35) -> 468353.97 | E35: =C35-D35 -> 7318.0308 | F35: ='Draw Calc (Hidden)'!C17 -> 43908.185 | G35: ='Draw Calc (Hidden)'!D17 -> 43908.185 | H35: ='Draw Calc (Hidden)'!E17 -> 43908.185 | I35: ='Draw Calc (Hidden)'!F17 -> 43908.185 | J35: ='Draw Calc (Hidden)'!G17 -> 43908.185 | K35: ='Draw Calc (Hidden)'!H17 -> 43908.185 | L35: ='Draw Calc (Hidden)'!I17 -> 29272.123 | M35: ='Draw Calc (Hidden)'!J17 -> 29272.123 | ... AO35: ='Draw Calc (Hidden)'!AL17 -> 0
... A188: ='I_Budget Input Data'!B170 -> HOLDBACKS | B188: ='I_Budget Input Data'!C170 -> 0 | C188: ='I_Budget Input Data'!D170 -> 0 | D188: =SUM(F188:AO188) -> 0 | E188: =C188-D188 -> 0 | F188: ='Draw Calc (Hidden)'!C170 -> 0 | G188: ='Draw Calc (Hidden)'!D170 -> 0 | H188: ='Draw Calc (Hidden)'!E170 -> 0 | I188: ='Draw Calc (Hidden)'!F170 -> 0 | J188: ='Draw Calc (Hidden)'!G170 -> 0 | K188: ='Draw Calc (Hidden)'!H170 -> 0 | L188: ='Draw Calc (Hidden)'!I170 -> 0 | M188: ='Draw Calc (Hidden)'!J170 -> 0 | ... AO188: ='Draw Calc (Hidden)'!AL170 -> 0
A190: TOTAL | B190: All Line Items | C190: =SUM(C24:C188) -> 43565725 | D190: =SUM(D24:D188) -> 43343780 | E190: =SUM(E24:E188) -> 221944.75 | F190: =SUM(F24:F188) -> 4759939 | G190: =SUM(G24:G188) -> 3034771 | H190: =SUM(H24:H188) -> 3034771 | I190: =SUM(I24:I188) -> 3279863.2 | J190: =SUM(J24:J188) -> 3279863.2 | ... AO190: =SUM(AO24:AO188) -> 0
A193: CONSTRUCTION PERIOD CASH FLOW
A194: Professional CFO-grade tracking - Subordinated sources deployed BEFORE Senior Loan
A196: Item | B196: Description | C196: Type | D196: Total | F196: ='Time Axis'!B4 -> 45747 | G196: ='Time Axis'!B5 -> 45777 | H196: ='Time Axis'!B6 -> 45808 | I196: ='Time Axis'!B7 -> 45838 | J196: ='Time Axis'!B8 -> 45869 | K196: ='Time Axis'!B9 -> 45900 | L196: ='Time Axis'!B10 -> 45930 | M196: ='Time Axis'!B11 -> 45961 | N196: ='Time Axis'!B12 -> 45991 | O196: ='Time Axis'!B13 -> 46022 | P196: ='Time Axis'!B14 -> 46053 | Q196: ='Time Axis'!B15 -> 46081 | R196: ='Time Axis'!B16 -> 46112 | S196: ='Time Axis'!B17 -> 46142 | T196: ='Time Axis'!B18 -> 46173 | U196: ='Time Axis'!B19 -> 46203 | V196: ='Time Axis'!B20 -> 46234 | W196: ='Time Axis'!B21 -> 46265 | X196: ='Time Axis'!B22 -> 46295 | Y196: ='Time Axis'!B23 -> 46326 | Z196: ='Time Axis'!B24 -> 46356 | AA196: ='Time Axis'!B25 -> 46387 | AB196: ='Time Axis'!B26 -> 46418 | AC196: ='Time Axis'!B27 -> 46446 | AD196: ='Time Axis'!B28 -> 46477 | AE196: ='Time Axis'!B29 -> 46507 | AF196: ='Time Axis'!B30 -> 46538 | AG196: ='Time Axis'!B31 -> 46568 | AH196: ='Time Axis'!B32 -> 46599 | AI196: ='Time Axis'!B33 -> 46630 | AJ196: ='Time Axis'!B34 -> 46660 | AK196: ='Time Axis'!B35 -> 46691 | AL196: ='Time Axis'!B36 -> 46721 | AM196: ='Time Axis'!B37 -> 46752 | AN196: ='Time Axis'!B38 -> 46783 | AO196: ='Time Axis'!B39 -> 46812
A197: OPENING BALANCE | B197: Cash at beginning of month | C197: Balance | D197: =F197 -> 0 | F197: 0 | G197: =F213 -> 5177402.9 | H197: =G213 -> 2142631.9 | I197: =H213 -> 100000 | J197: =I213 -> 100000 | K197: =J213 -> 100000 | L197: =K213 -> 100000 | M197: =L213 -> 100000 | N197: =M213 -> 100000 | ... AO197: =AN213 -> 100000
A198: CASH INFLOWS | B198: Sources of cash
A199: 1. Class A Equity (Land) | B199: From Sources & Uses - upfront | C199: Input | D199: =IFERROR('Sources & Uses - Construction'!B6,0) -> 15 | F199: =D199 -> 15 | G199: 0 | H199: 0 | I199: 0 | J199: 0 | K199: 0 | L199: 0 | M199: 0 | N199: 0 | O199: 0 | P199: 0 | Q199: 0 | R199: 0 | S199: 0 | T199: 0 | U199: 0 | V199: 0 | W199: 0 | X199: 0 | Y199: 0 | Z199: 0 | AA199: 0 | AB199: 0 | AC199: 0 | AD199: 0 | AE199: 0 | AF199: 0 | AG199: 0 | AH199: 0 | AI199: 0 | AJ199: 0 | AK199: 0 | AL199: 0 | AM199: 0 | AN199: 0 | AO199: 0
A200: 2. Class E Equity Calls | B200: From Sources & Uses - as needed | C200: Input | D200: =IFERROR('Sources & Uses - Construction'!B7,0) -> 2800015 | F200: =D200 -> 2800015 | G200: 0 | H200: 0 | I200: 0 | J200: 0 | K200: 0 | L200: 0 | M200: 0 | N200: 0 | O200: 0 | P200: 0 | Q200: 0 | R200: 0 | S200: 0 | T200: 0 | U200: 0 | V200: 0 | W200: 0 | X200: 0 | Y200: 0 | Z200: 0 | AA200: 0 | AB200: 0 | AC200: 0 | AD200: 0 | AE200: 0 | AF200: 0 | AG200: 0 | AH200: 0 | AI200: 0 | AJ200: 0 | AK200: 0 | AL200: 0 | AM200: 0 | AN200: 0 | AO200: 0
...

Sheet Sources & Uses - Construction
A1: SOURCES & USES - CONSTRUCTION PERIOD
A2: Static summary of construction funding
A4: SOURCES OF FUNDS | B4: Amount
A5: In disbursement priority order (1→5)
A6: 1. Class A Equity (GP - Land Contribution) | B6: ='i_Cap Table'!C15 -> 15 | C6: Land contribution (upfront)
A7: 2. Class E Equity (LP Units) | B7: ='i_Cap Table'!E34 -> 2800015 | C7: From Cap Table - called during construction
A8: 3. Subordinated Loan #1 (Preferred Equity) | B8: ='I_Preferred Equity'!C17 -> 0 | C8: From Preferred Equity table
A9: 4. Subordinated Loan #2 (Mezzanine) | B9: ='I_Mezzanine Debt'!C17 -> 0 | C9: From Mezzanine Debt table
A11: Required Additional Equity | B11: =B32-B13-SUM(B5:B9) -> 7137311.9 | C11: Calculated gap - additional equity needed
A13: 5. Senior Construction Loan | B13: ='Senior Construction Financing'!B9 -> 33628383 | C13: Residual only - after all subordinated
A16: TOTAL SOURCES | B16: =SUM(B6:B14)-B10 -> 43565725
A19: USES OF FUNDS | B19: Amount
A20: 1. LAND | B20: =SUMIF('I_Budget Input Data'!$B:$B,"1. LAND",'I_Budget Input Data'!$D:$D) -> 1725168
A21: 2. SITE SERVICING + LANDSCAPE | B21: =SUMIF('I_Budget Input Data'!$B:$B,"2. SITE SERVICING + LANDSCAPE",'I_Budget Input Data'!$D:$D) -> 5168121
A22: 3. HARD COSTS | B22: =SUMIF('I_Budget Input Data'!$B:$B,"3. HARD COSTS",'I_Budget Input Data'!$D:$D) -> 25732155
A23: 4. FF&E | B23: =SUMIF('I_Budget Input Data'!$B:$B,"4. FF&E",'I_Budget Input Data'!$D:$D) -> 1792768
A24: 5. PROFESSIONAL FEES | B24: =SUMIF('I_Budget Input Data'!$B:$B,"5. PROFESSIONAL FEES",'I_Budget Input Data'!$D:$D) -> 3283546
A25: 6. FINANCE AND ADMINISTRATION | B25: =SUMIF('I_Budget Input Data'!$B:$B,"6. FINANCE AND ADMINISTRATION",'I_Budget Input Data'!$D:$D) -> 3276350
A26: 7. TAX ASSESSMENT | B26: =SUMIF('I_Budget Input Data'!$B:$B,"7. TAX ASSESSMENT",'I_Budget Input Data'!$D:$D) -> 2087617
A27: 8. CONTINGENCY ALLOWANCE | B27: =SUMIF('I_Budget Input Data'!$B:$B,"8. CONTINGENCY ALLOWANCE",'I_Budget Input Data'!$D:$D) -> 500000
A28: Capitalized Interest | B28: =IFERROR('Senior Construction Financing'!B56, 0) -> 0
A29: GST/QST Paid (Gross) | B29: 0 | C29: Set to $0
A32: TOTAL USES | B32: =SUM(B19:B29) -> 43565725
A35: RECONCILIATION
A36: Total Sources | B36: =B16 -> 43565725
A37: Total Uses | B37: =B32 -> 43565725
A38: Difference (Should be $0) | B38: =B36-B37 -> 0
A39: Status | B39: =IF(ABS(B38)<1,"✓ BALANCED","✗ NOT BALANCED") -> ✓ BALANCED

Sheet Senior Construction Financing
A1: SENIOR CONSTRUCTION FINANCING
A2: Monthly tracking of construction loan draws, interest, and equity calls
A4: LOAN PARAMETERS
A5: Loan-to-Cost (LTC): | B5: ='I_Inputs & Assumptions'!B36 -> 0.7719
A6: Interest Rate (Annual): | B6: ='I_Inputs & Assumptions'!B37 -> 0.0495
A7: Commitment Fee: | B7: ='I_Inputs & Assumptions'!B38 -> 0.001
A8: Total Project Cost (from Budget): | B8: ='Construction Budget & Draws'!C190 -> 43565725
A9: Maximum Loan Amount (LTC × Cost): | B9: =B8*B5 -> 33628383
A12: MONTHLY CONSTRUCTION LOAN SCHEDULE
A13: Month | B13: Date | C13: Phase | D13: Beg Balance | E13: Construction Draws | F13: Less: Holdback (10%) | G13: Net Draw | H13: Senior Loan Advance | I13: Interest Accrued | J13: Commitment Fee | K13: End Balance | L13: Cumul Cap Interest | M13: Equity Called (Class E) | N13: Cash Balance Check
A14: 1 | B14: ='Time Axis'!B4 -> 45747 | C14: ='Time Axis'!C4 -> Construction | D14: 0 | E14: ='Construction Budget & Draws'!F$190 -> 4759939 | F14: =-E14*0.1 -> -475993.9 | G14: =E14+F14 -> 4283945.1 | H14: {=TRANSPOSE('Construction Budget & Draws'!F204:AO204)} -> 0 | I14: =IF(C14="Construction",(D14)*$B$6/12,0) -> 0 | J14: =$B$9*$B$7 -> 33628.383 | N14: =#REF!+M14-G14 -> #REF!
A15: 2 | B15: ='Time Axis'!B5 -> 45777 | C15: ='Time Axis'!C5 -> Construction | D15: =K14 -> 0 | E15: ='Construction Budget & Draws'!G$190 -> 3034771 | F15: =-E15*0.1 -> -303477.1 | G15: =E15+F15 -> 2731293.9 | H15: 0 | I15: =IF(C15="Construction",(D15)*$B$6/12,0) -> 0 | J15: 0 | N15: =H15+M15-G15 -> -2731293.9
A16: 3 | B16: ='Time Axis'!B6 -> 45808 | C16: ='Time Axis'!C6 -> Construction | D16: =K15 -> 0 | E16: ='Construction Budget & Draws'!H$190 -> 3034771 | F16: =-E16*0.1 -> -303477.1 | G16: =E16+F16 -> 2731293.9 | H16: 992139.13 | I16: =IF(C16="Construction",(D16)*$B$6/12,0) -> 0 | J16: 0 | N16: =H16+M16-G16 -> -1739154.8
A17: 4 | B17: ='Time Axis'!B7 -> 45838 | C17: ='Time Axis'!C7 -> Construction | D17: =K16 -> 0 | E17: ='Construction Budget & Draws'!I$190 -> 3279863.2 | F17: =-E17*0.1 -> -327986.32 | G17: =E17+F17 -> 2951876.9 | H17: 3279863.2 | I17: =IF(C17="Construction",(D17)*$B$6/12,0) -> 0 | J17: 0 | N17: =H17+M17-G17 -> 327986.32
A18: 5 | B18: ='Time Axis'!B8 -> 45869 | C18: ='Time Axis'!C8 -> Construction | D18: =K17 -> 0 | E18: ='Construction Budget & Draws'!J$190 -> 3279863.2 | F18: =-E18*0.1 -> -327986.32 | G18: =E18+F18 -> 2951876.9 | H18: 3279863.2 | I18: =IF(C18="Construction",(D18)*$B$6/12,0) -> 0 | J18: 0 | N18: =H18+M18-G18 -> 327986.32
A19: 6 | B19: ='Time Axis'!B9 -> 45900 | C19: ='Time Axis'!C9 -> Construction | D19: =K18 -> 0 | E19: ='Construction Budget & Draws'!K$190 -> 3279863.2 | F19: =-E19*0.1 -> -327986.32 | G19: =E19+F19 -> 2951876.9 | H19: 3279863.2 | I19: =IF(C19="Construction",(D19)*$B$6/12,0) -> 0 | J19: 0 | N19: =H19+M19-G19 -> 327986.32
A20: 7 | B20: ='Time Axis'!B10 -> 45930 | C20: ='Time Axis'!C10 -> Construction | D20: =K19 -> 0 | E20: ='Construction Budget & Draws'!L$190 -> 3081065.9 | F20: =-E20*0.1 -> -308106.59 | G20: =E20+F20 -> 2772959.3 | H20: 3081065.9 | I20: =IF(C20="Construction",(D20)*$B$6/12,0) -> 0 | J20: 0 | N20: =H20+M20-G20 -> 308106.59
A21: 8 | B21: ='Time Axis'!B11 -> 45961 | C21: ='Time Axis'!C11 -> Construction | D21: =K20 -> 0 | E21: ='Construction Budget & Draws'!M$190 -> 3081065.9 | F21: =-E21*0.1 -> -308106.59 | G21: =E21+F21 -> 2772959.3 | H21: 3081065.9 | I21: =IF(C21="Construction",(D21)*$B$6/12,0) -> 0 | J21: 0 | N21: =H21+M21-G21 -> 308106.59
A22: 9 | B22: ='Time Axis'!B12 -> 45991 | C22: ='Time Axis'!C12 -> Construction | D22: =K21 -> 0 | E22: ='Construction Budget & Draws'!N$190 -> 3081065.9 | F22: =-E22*0.1 -> -308106.59 | G22: =E22+F22 -> 2772959.3 | H22: 3081065.9 | I22: =IF(C22="Construction",(D22)*$B$6/12,0) -> 0 | J22: 0 | N22: =H22+M22-G22 -> 308106.59
A23: 10 | B23: ='Time Axis'!B13 -> 46022 | C23: ='Time Axis'!C13 -> Construction | D23: =K22 -> 0 | E23: ='Construction Budget & Draws'!O$190 -> 2835973.7 | F23: =-E23*0.1 -> -283597.37 | G23: =E23+F23 -> 2552376.3 | H23: 2835973.7 | I23: =IF(C23="Construction",(D23)*$B$6/12,0) -> 0 | J23: 0 | N23: =H23+M23-G23 -> 283597.37
A24: 11 | B24: ='Time Axis'!B14 -> 46053 | C24: ='Time Axis'!C14 -> Construction | D24: =K23 -> 0 | E24: ='Construction Budget & Draws'!P$190 -> 2835973.7 | F24: =-E24*0.1 -> -283597.37 | G24: =E24+F24 -> 2552376.3 | H24: 2835973.7 | I24: =IF(C24="Construction",(D24)*$B$6/12,0) -> 0 | J24: 0 | N24: =H24+M24-G24 -> 283597.37
A25: 12 | B25: ='Time Axis'!B15 -> 46081 | C25: ='Time Axis'!C15 -> Construction | D25: =K24 -> 0 | E25: ='Construction Budget & Draws'!Q$190 -> 2835973.7 | F25: =-E25*0.1 -> -283597.37 | G25: =E25+F25 -> 2552376.3 | H25: 2835973.7 | I25: =IF(C25="Construction",(D25)*$B$6/12,0) -> 0 | J25: 0 | N25: =H25+M25-G25 -> 283597.37
A26: 13 | B26: ='Time Axis'!B16 -> 46112 | C26: ='Time Axis'!C16 -> Construction | D26: =K25 -> 0 | E26: ='Construction Budget & Draws'!R$190 -> 4923590.7 | F26: =-E26*0.1 -> -492359.07 | G26: =E26+F26 -> 4431231.6 | H26: 4923590.7 | I26: =IF(C26="Construction",(D26)*$B$6/12,0) -> 0 | J26: 0 | N26: =H26+M26-G26 -> 492359.07
A27: 14 | B27: ='Time Axis'!B17 -> 46142 | C27: ='Time Axis'!C17 -> Lease-Up | D27: =K26 -> 0 | E27: ='Construction Budget & Draws'!S$190 -> 0 | F27: =-E27*0.1 -> 0 | G27: =E27+F27 -> 0 | H27: 0 | I27: =IF(C27="Construction",(D27)*$B$6/12,0) -> 0 | J27: 0 | N27: =H27+M27-G27 -> 0
A28: 15 | B28: ='Time Axis'!B18 -> 46173 | C28: ='Time Axis'!C18 -> Stabilized | D28: =K27 -> 0 | E28: ='Construction Budget & Draws'!T$190 -> 0 | F28: =-E28*0.1 -> 0 | G28: =E28+F28 -> 0 | H28: 0 | I28: =IF(C28="Construction",(D28)*$B$6/12,0) -> 0 | J28: 0 | N28: =H28+M28-G28 -> 0
A29: 16 | B29: ='Time Axis'!B19 -> 46203 | C29: ='Time Axis'!C19 -> Stabilized | D29: =K28 -> 0 | E29: ='Construction Budget & Draws'!U$190 -> 0 | F29: =-E29*0.1 -> 0 | G29: =E29+F29 -> 0 | H29: 0 | I29: =IF(C29="Construction",(D29)*$B$6/12,0) -> 0 | J29: 0 | N29: =H29+M29-G29 -> 0
A30: 17 | B30: ='Time Axis'!B20 -> 46234 | C30: ='Time Axis'!C20 -> Stabilized | D30: =K29 -> 0 | E30: ='Construction Budget & Draws'!V$190 -> 0 | F30: =-E30*0.1 -> 0 | G30: =E30+F30 -> 0 | H30: 0 | I30: =IF(C30="Construction",(D30)*$B$6/12,0) -> 0 | J30: 0 | N30: =H30+M30-G30 -> 0
A31: 18 | B31: ='Time Axis'!B21 -> 46265 | C31: ='Time Axis'!C21 -> Stabilized | D31: =K30 -> 0 | E31: ='Construction Budget & Draws'!W$190 -> 0 | F31: =-E31*0.1 -> 0 | G31: =E31+F31 -> 0 | H31: 0 | I31: =IF(C31="Construction",(D31)*$B$6/12,0) -> 0 | J31: 0 | N31: =H31+M31-G31 -> 0
A32: 19 | B32: ='Time Axis'!B22 -> 46295 | C32: ='Time Axis'!C22 -> Stabilized | D32: =K31 -> 0 | E32: ='Construction Budget & Draws'!X$190 -> 0 | F32: =-E32*0.1 -> 0 | G32: =E32+F32 -> 0 | H32: 0 | I32: =IF(C32="Construction",(D32)*$B$6/12,0) -> 0 | J32: 0 | N32: =H32+M32-G32 -> 0
A33: 20 | B33: ='Time Axis'!B23 -> 46326 | C33: ='Time Axis'!C23 -> Stabilized | D33: =K32 -> 0 | E33: ='Construction Budget & Draws'!Y$190 -> 0 | F33: =-E33*0.1 -> 0 | G33: =E33+F33 -> 0 | H33: 0 | I33: =IF(C33="Construction",(D33)*$B$6/12,0) -> 0 | J33: 0 | N33: =H33+M33-G33 -> 0
A34: 21 | B34: ='Time Axis'!B24 -> 46356 | C34: ='Time Axis'!C24 -> Stabilized | D34: =K33 -> 0 | E34: ='Construction Budget & Draws'!Z$190 -> 0 | F34: =-E34*0.1 -> 0 | G34: =E34+F34 -> 0 | H34: 0 | I34: =IF(C34="Construction",(D34)*$B$6/12,0) -> 0 | J34: 0 | N34: =H34+M34-G34 -> 0
A35: 22 | B35: ='Time Axis'!B25 -> 46387 | C35: ='Time Axis'!C25 -> Stabilized | D35: =K34 -> 0 | E35: ='Construction Budget & Draws'!AA$190 -> 0 | F35: =-E35*0.1 -> 0 | G35: =E35+F35 -> 0 | H35: 0 | I35: =IF(C35="Construction",(D35)*$B$6/12,0) -> 0 | J35: 0 | N35: =H35+M35-G35 -> 0
A36: 23 | B36: ='Time Axis'!B26 -> 46418 | C36: ='Time Axis'!C26 -> Stabilized | D36: =K35 -> 0 | E36: ='Construction Budget & Draws'!AB$190 -> 0 | F36: =-E36*0.1 -> 0 | G36: =E36+F36 -> 0 | H36: 0 | I36: =IF(C36="Construction",(D36)*$B$6/12,0) -> 0 | J36: 0 | N36: =H36+M36-G36 -> 0
A37: 24 | B37: ='Time Axis'!B27 -> 46446 | C37: ='Time Axis'!C27 -> Stabilized | D37: =K36 -> 0 | E37: ='Construction Budget & Draws'!AC$190 -> 0 | F37: =-E37*0.1 -> 0 | G37: =E37+F37 -> 0 | H37: 0 | I37: =IF(C37="Construction",(D37)*$B$6/12,0) -> 0 | J37: 0 | N37: =H37+M37-G37 -> 0
A38: 25 | B38: ='Time Axis'!B28 -> 46477 | C38: ='Time Axis'!C28 -> Stabilized | D38: =K37 -> 0 | E38: ='Construction Budget & Draws'!AD$190 -> 0 | F38: =-E38*0.1 -> 0 | G38: =E38+F38 -> 0 | H38: 0 | I38: =IF(C38="Construction",(D38)*$B$6/12,0) -> 0 | J38: 0 | N38: =H38+M38-G38 -> 0
A39: 26 | B39: ='Time Axis'!B29 -> 46507 | C39: ='Time Axis'!C29 -> Stabilized | D39: =K38 -> 0 | E39: ='Construction Budget & Draws'!AE$190 -> 0 | F39: =-E39*0.1 -> 0 | G39: =E39+F39 -> 0 | H39: 0 | I39: =IF(C39="Construction",(D39)*$B$6/12,0) -> 0 | J39: 0 | N39: =H39+M39-G39 -> 0
A40: 27 | B40: ='Time Axis'!B30 -> 46538 | C40: ='Time Axis'!C30 -> Stabilized | D40: =K39 -> 0 | E40: ='Construction Budget & Draws'!AF$190 -> 0 | F40: =-E40*0.1 -> 0 | G40: =E40+F40 -> 0 | H40: 0 | I40: =IF(C40="Construction",(D40)*$B$6/12,0) -> 0 | J40: 0 | N40: =H40+M40-G40 -> 0
A41: 28 | B41: ='Time Axis'!B31 -> 46568 | C41: ='Time Axis'!C31 -> Stabilized | D41: =K40 -> 0 | E41: ='Construction Budget & Draws'!AG$190 -> 0 | F41: =-E41*0.1 -> 0 | G41: =E41+F41 -> 0 | H41: 0 | I41: =IF(C41="Construction",(D41)*$B$6/12,0) -> 0 | J41: 0 | N41: =H41+M41-G41 -> 0
A42: 29 | B42: ='Time Axis'!B32 -> 46599 | C42: ='Time Axis'!C32 -> Stabilized | D42: =K41 -> 0 | E42: ='Construction Budget & Draws'!AH$190 -> 0 | F42: =-E42*0.1 -> 0 | G42: =E42+F42 -> 0 | H42: 0 | I42: =IF(C42="Construction",(D42)*$B$6/12,0) -> 0 | J42: 0 | N42: =H42+M42-G42 -> 0
A43: 30 | B43: ='Time Axis'!B33 -> 46630 | C43: ='Time Axis'!C33 -> Stabilized | D43: =K42 -> 0 | E43: ='Construction Budget & Draws'!AI$190 -> 0 | F43: =-E43*0.1 -> 0 | G43: =E43+F43 -> 0 | H43: 0 | I43: =IF(C43="Construction",(D43)*$B$6/12,0) -> 0 | J43: 0 | N43: =H43+M43-G43 -> 0
...

Sheet Draw Calc (Hidden)
A1: DETAILED PHASING CALCULATION
A2: Row alignment matches Budget Input Data exactly
A4: Category | B4: Subcategory | C4: Mo 1 | D4: Mo 2 | E4: Mo 3 | F4: Mo 4 | G4: Mo 5 | H4: Mo 6 | I4: Mo 7 | J4: Mo 8 | K4: Mo 9 | L4: Mo 10 | M4: Mo 11 | N4: Mo 12 | O4: Mo 13 | P4: Mo 14 | Q4: Mo 15 | R4: Mo 16 | S4: Mo 17 | T4: Mo 18 | U4: Mo 19 | V4: Mo 20 | W4: Mo 21 | X4: Mo 22 | Y4: Mo 23 | Z4: Mo 24 | AA4: Mo 25 | AB4: Mo 26 | AC4: Mo 27 | AD4: Mo 28 | AE4: Mo 29 | AF4: Mo 30 | AG4: Mo 31 | AH4: Mo 32 | AI4: Mo 33 | AJ4: Mo 34 | AK4: Mo 35 | AL4: Mo 36
C5: 0 | D5: 0 | E5: 0 | F5: 0 | G5: 0 | H5: 0 | I5: 0 | J5: 0 | K5: 0 | L5: 0 | M5: 0 | N5: 0 | O5: 0 | P5: 0 | Q5: 0 | R5: 0 | S5: 0 | T5: 0 | U5: 0 | V5: 0 | W5: 0 | X5: 0 | Y5: 0 | Z5: 0 | AA5: 0 | AB5: 0 | AC5: 0 | AD5: 0 | AE5: 0 | AF5: 0 | AG5: 0 | AH5: 0 | AI5: 0 | AJ5: 0 | AK5: 0 | AL5: 0
