Workbook

Sheet I_Inputs & Assumptions
A1: CONSTRUCTION-TO-PERMANENT FINANCIAL MODEL
A2: INPUTS & ASSUMPTIONS
A4: PROJECT INFORMATION
A5: Project Name | B5: Campus Adele
A6: Location | B6: Quebec
A7: Construction Start Date | B7: 2025-03-01
A8: Construction Duration | B8: 13 | C8: months
A9: Months Until First Units Ready | B9: 16 | C9: months
A10: Gap to Permanent Financing | B10: 1 | C10: months
A11: Permanent Loan Term | B11: 60 | C11: months
A12: Exit Timing (Post-Construction) | B12: 61 | C12: months
A14: CONSTRUCTION BUDGET
A15: Land - Purchase Price | B15: 400000
A16: Land - Recognized Value | B16: 600000
A17: Assessed Property Value | B17: 15000000
A18: Hard Costs by Category | B18: Budget | C18: Phasing % | D18: Holdback % | E18: Release (mo)
A19: Site Work & Demolition | B19: 500000 | C19: Equal | D19: 0.1 | E19: 3
A20: Foundation & Structure | B20: 3000000 | C20: Front-loaded | D20: 0.1 | E20: 2
A21: Building Envelope | B21: 2000000 | C21: Mid-weighted | D21: 0.1 | E21: 3
A22: MEP Systems | B22: 2500000 | C22: Mid-weighted | D22: 0.1 | E22: 4
A23: Interior Finishes | B23: 1500000 | C23: Back-loaded | D23: 0.1 | E23: 2
A24: Landscaping & Site | B24: 300000 | C24: Back-loaded | D24: 0.1 | E24: 6
A26: Soft Costs by Category | B26: Budget | C26: Holdback %
A27: Architecture & Engineering | B27: 400000 | C27: 0.1
A28: Permits & Approvals | B28: 150000 | C28: 0
A29: Legal & Financing Fees | B29: 200000 | C29: 0
A30: Development Management | B30: 300000 | C30: 0.1
A31: Marketing & Leasing | B31: 100000 | C31: 0
A33: Contingency | B33: 500000
A35: CONSTRUCTION FINANCING - SENIOR LOAN
A36: Loan-to-Cost (LTC) % | B36: 0.7719 | C36: % | G36: ='Sources & Uses - Construction'!A4 | H36: ='Sources & Uses - Construction'!B4
A37: Interest Rate (Annual) | B37: 0.0495 | C37: % | G37: ='Sources & Uses - Construction'!A5 | H37: ='Sources & Uses - Construction'!B5
A38: Commitment Fee | B38: 0.001 | C38: % | G38: ='Sources & Uses - Construction'!A6 | H38: ='Sources & Uses - Construction'!B6
A39: Loan Amount | B39: 33627000 | C39: % | G39: ='Sources & Uses - Construction'!A7 | H39: ='Sources & Uses - Construction'!B7
A40: SUBORDINATED LOAN #1 - PREFERRED EQUITY | G40: ='Sources & Uses - Construction'!A8 | H40: ='Sources & Uses - Construction'!B8
A41: Loan Amount | B41: 0 | G41: ='Sources & Uses - Construction'!A9 | H41: ='Sources & Uses - Construction'!B9
A42: Interest Rate (Annual) | B42: 0.08 | C42: % | G42: ='Sources & Uses - Construction'!A10 | H42: ='Sources & Uses - Construction'!B10
A43: Commitment Fee | B43: 0.001 | C43: % | G43: ='Sources & Uses - Construction'!A11 | H43: ='Sources & Uses - Construction'!B11
A44: Draw Priority | B44: 1 | G44: ='Sources & Uses - Construction'!A12 | H44: ='Sources & Uses - Construction'!B12
G45: ='Sources & Uses - Construction'!A13 | H45: ='Sources & Uses - Construction'!B13
...

Sheet I_Budget Input Data
A1: BUDGET INPUT DATA
A2: Imported from ryanbudget.csv - Edit phasing, holdback, and eligibility as needed
A4: Row # | B4: Category | C4: Subcategory | D4: Budget Amount | E4: Phasing Pattern | F4: Holdback % | G4: Holdback Release (mo after constr) | H4: GST/QST Eligible
A5: 1 | D5: 0 | E5: Equal | F5: 0.1 | G5: 3 | H5: Yes
A6: 2 | B6: 1. LAND | C6: Land Acquisition | D6: 1600000 | E6: Upfront | F6: 0 | G6: 0 | H6: Yes
A7: 3 | B7: 1. LAND | C7: Notary and cadastre | D7: 19808 | E7: Upfront | F7: 0 | G7: 0 | H7: Yes
A8: 4 | B8: 1. LAND | C8: Cadastral operation | D8: 105360 | E8: Upfront | F8: 0 | G8: 0 | H8: Yes
A9: 5 | B9: 2. SITE SERVICING + LANDSCAPE | C9: Extension of services:Excavation & Backfill - Adjustment for Bldgs 5 & 6 | D9: 479320 | E9: Front-loaded | F9: 0.1 | G9: 3 | H9: Yes
A10: 6 | B10: 2. SITE SERVICING + LANDSCAPE | C10: Extension of services:Excavation & Backfill - Trailer pad, Access road, Septic tank | D10: 10900 | E10: Front-loaded | F10: 0.1 | G10: 3 | H10: Yes
A11: 7 | B11: 2. SITE SERVICING + LANDSCAPE | C11: Extension of services:Credit - Reservoir change | D11: 1946765 | E11: Front-loaded | F11: 0.1 | G11: 3 | H11: Yes
A12: 8 | B12: 2. SITE SERVICING + LANDSCAPE | C12: Extension of services:Credit - Reservoir change | D12: 0 | E12: Front-loaded | F12: 0.1 | G12: 3 | H12: Yes
A13: 9 | B13: 2. SITE SERVICING + LANDSCAPE | C13: Extension of services:Excavation & Backfill - Campus Civil | D13: 143113 | E13: Front-loaded | F13: 0.1 | G13: 3 | H13: Yes
A14: 10 | B14: 2. SITE SERVICING + LANDSCAPE | C14: Extension of services:Excavation & Backfill - Campus Civil | D14: 30493 | E14: Front-loaded | F14: 0.1 | G14: 3 | H14: Yes
A15: 11 | B15: 2. SITE SERVICING + LANDSCAPE | C15: Extension of services:Excavation & backfill - Extension - Mtee Ryan Civil | D15: 375295 | E15: Front-loaded | F15: 0.1 | G15: 3 | H15: Yes
A16: 12 | B16: 2. SITE SERVICING + LANDSCAPE | D16: 165563 | E16: Front-loaded | F16: 0.1 | G16: 3 | H16: Yes
A17: 13 | B17: 2. SITE SERVICING + LANDSCAPE | C17: Onsite services - civil:Excavation & Backfill (PC) | D17: 475672 | E17: Front-loaded | F17: 0.1 | G17: 3 | H17: Yes
A18: 14 | B18: 2. SITE SERVICING + LANDSCAPE | C18: Onsite services - civil:Excavation & Backfill (PC) | D18: 23100 | E18: Front-loaded | F18: 0.1 | G18: 3 | H18: Yes
A19: 15 | B19: 2. SITE SERVICING + LANDSCAPE | C19: Onsite services - civil:Excavation & Backfill (PC) | D19: 2300 | E19: Front-loaded | F19: 0.1 | G19: 3 | H19: Yes
A20: 16 | B20: 2. SITE SERVICING + LANDSCAPE | C20: Onsite services - civil:Excavation & Backfill (PC) | D20: 25102 | E20: Front-loaded | F20: 0.1 | G20: 3 | H20: Yes
A21: 17 | B21: 2. SITE SERVICING + LANDSCAPE | C21: Onsite services - civil:Excavation & Backfill (PC) | D21: 47223 | E21: Front-loaded | F21: 0.1 | G21: 3 | H21: Yes
A22: 18 | B22: 2. SITE SERVICING + LANDSCAPE | C22: Landscaping:Excavation & Backfill - Landscaping | D22: 1065794 | E22: Front-loaded | F22: 0.1 | G22: 3 | H22: Yes
A23: 19 | B23: 2. SITE SERVICING + LANDSCAPE | C23: Electrical services | D23: 252500 | E23: Front-loaded | F23: 0.1 | G23: 3 | H23: Yes
A24: 20 | B24: 2. SITE SERVICING + LANDSCAPE | C24: Electrical charging stations | D24: 124981 | E24: Front-loaded | F24: 0.1 | G24: 3 | H24: Yes
A25: 21 | B25: 3. HARD COSTS | C25: Admin and profit | D25: 1577987 | E25: Equal | F25: 0.1 | G25: 3 | H25: Yes
A26: 22 | B26: 3. HARD COSTS | C26: Insurance and bonding:Insurance | D26: 278718 | E26: Equal | F26: 0.1 | G26: 3 | H26: Yes
A27: 23 | B27: 3. HARD COSTS | D27: 140525 | E27: Equal | F27: 0.1 | G27: 3 | H27: Yes
A28: 24 | B28: 3. HARD COSTS | C28: Insurance and bonding:Wrap-up | D28: 36465 | E28: Equal | F28: 0.1 | G28: 3 | H28: Yes
A29: 25 | B29: 3. HARD COSTS | C29: Insurance and bonding:Bris des Machines | D29: 2585 | E29: Equal | F29: 0.1 | G29: 3 | H29: Yes
A30: 26 | B30: 3. HARD COSTS | C30: Insurance and bonding:L&M and Performance Bonds | D30: 0 | E30: Equal | F30: 0.1 | G30: 3 | H30: Yes
A31: 27 | B31: 3. HARD COSTS | C31: General conditions:CoSS Agent | D31: 236000 | E31: Equal | F31: 0.1 | G31: 3 | H31: Yes
A32: 28 | B32: 3. HARD COSTS | C32: General conditions:RSS Agent | D32: 213500 | E32: Equal | F32: 0.1 | G32: 3 | H32: Yes
A33: 29 | B33: 3. HARD COSTS | C33: General conditions:Superintendent 1 | D33: 303400 | E33: Equal | F33: 0.1 | G33: 3 | H33: Yes
A34: 30 | B34: 3. HARD COSTS | C34: General conditions:Superintendent 2 | D34: 266400 | E34: Equal | F34: 0.1 | G34: 3 | H34: Yes
A35: 31 | B35: 3. HARD COSTS | C35: General conditions:Project Manager | D35: 150750 | E35: Equal | F35: 0.1 | G35: 3 | H35: Yes
A36: 32 | B36: 3. HARD COSTS | C36: General conditions:Labourer | D36: 230020 | E36: Equal | F36: 0.1 | G36: 3 | H36: Yes
A37: 33 | B37: 3. HARD COSTS | C37: General Conditions: Logding | D37: 11000 | E37: Equal | F37: 0.1 | G37: 3 | H37: Yes
A38: 34 | B38: 3. HARD COSTS | C38: General conditions:Site fencing | D38: 10780 | E38: Equal | F38: 0.1 | G38: 3 | H38: Yes
A39: 35 | B39: 3. HARD COSTS | C39: General Conditions: Printing | D39: 8048 | E39: Equal | F39: 0.1 | G39: 3 | H39: Yes
... A57: 53 | B57: 3. HARD COSTS | C57: General conditions:Project signage | D57: 181830 | E57: Equal | F57: 0.1 | G57: 3 | H57: Yes
A58: 54 | B58: 3. HARD COSTS | D58: 6000 | E58: Equal | F58: 0.1 | G58: 3 | H58: Yes
...

Sheet I_Unit Rent Roll Data
A1: UNIT RENT ROLL DATA
A2: Exact import from Units-Proforma_View_Tremb.csv
A4: UnitId | B4: UnitRentalTypes | C4: Unit # | D4: Planned Delivery Date for Occupancy | E4: Projected Price Per Bedroom (from UnitRentalTypes) | F4: Projected Rate | G4: Bedroom Count (from UnitRentalTypes) | H4: Units Operations ID
A5: ADELE 1 A-101 | B5: London | C5: 101 | F5: 1905 | H5: ADELE -101 | I5: =F5*G5
A6: ADELE 1 A-201 | B6: Berlin | C6: 201 | F6: 2455 | H6: ADELE -201 | I6: =F6*G6
A7: ADELE 1 A-301 | B7: Berlin | C7: 301 | F7: 2455 | H7: ADELE -301
A8: ADELE 1 A-102 | B8: London | C8: 102 | F8: 1905 | H8: ADELE -102
A9: ADELE 1 A-202 | B9: Berlin | C9: 202 | F9: 2455 | H9: ADELE -202
A10: ADELE 1 A-302 | B10: Berlin | C10: 302 | F10: 2455 | H10: ADELE -302
A11: ADELE 1 B-101 | B11: London | C11: 101 | F11: 1905 | H11: ADELE -101
A12: ADELE 1 B-201 | B12: Paris | C12: 201 | F12: 1639 | H12: ADELE -201
A13: ADELE 1 B-202 | B13: New York | C13: 202 | F13: 1589 | H13: ADELE -202
A14: ADELE 1 B-301 | B14: Paris | C14: 301 | F14: 1639 | H14: ADELE -301
A15: ADELE 1 B-302 | B15: New York | C15: 302 | F15: 1589 | H15: ADELE -302
A16: ADELE 1 B-102 | B16: London | C16: 102 | F16: 1905 | H16: ADELE -102
A17: ADELE 1 B-202 | B17: Paris | C17: 202 | F17: 1639 | H17: ADELE -202
A18: ADELE 1 B-203 | B18: New York | C18: 203 | F18: 1589 | H18: ADELE -203
... A68: ADELE 3 H-302 | B68: New York | C68: 302 | F68: 1589 | H68: ADELE -302

Sheet I_Preferred Equity
A1: PREFERRED EQUITY TABLE
A2: Subordinated Loan #1 - Preferred Equity investors
A4: PREFERRED EQUITY INVESTORS
A5: ID | B5: Investor Name | C5: Contribution Amount | D5: Interest Rate | E5: Notes
A6: PE1 | C6: 0 | D6: 0
A7: PE2 | C7: 0 | D7: 0
A8: PE3 | C8: 0 | D8: 0
A9: PE4 | C9: 0 | D9: 0
A10: PE5 | C10: 0 | D10: 0
A11: PE6 | B11: =B32-B13-B10*2 | C11: 0 | D11: 0
A12: PE7 | C12: 0 | D12: 0
A13: PE8 | C13: 0 | D13: 0
A14: PE9 | C14: 0 | D14: 0
A15: PE10 | C15: 0 | D15: 0
A17: TOTAL | B17: Preferred Equity | C17: =SUM(C6:C15) | D17: Weighted Avg: | E17: =SUMPRODUCT(C6:C15,D6:D15)/C17
A20: INSTRUCTIONS:
A21: • Enter investor names in column B (yellow cells)
A22: • Enter contribution amounts in column C (yellow cells)
A23: • Enter interest rates in column D (yellow cells)
A24: • Add any notes in column E
A25: • Total will update automatically
A26: • This total is linked to Sources & Uses - Construction
B30: =-B13
B36: =B16
B37: =B32
B38: =B36-B37

Sheet I_Mezzanine Debt
A1: MEZZANINE DEBT TABLE
A2: Subordinated Loan #2 - Mezzanine lenders
A4: MEZZANINE LENDERS
A5: ID | B5: Lender Name | C5: Loan Amount | D5: Interest Rate | E5: Notes
A6: MEZZ1 | C6: 0 | D6: 0
A7: MEZZ2 | C7: 0 | D7: 0
A8: MEZZ3 | C8: 0 | D8: 0
A9: MEZZ4 | C9: 0 | D9: 0
A10: MEZZ5 | C10: 0 | D10: 0
A11: MEZZ6 | C11: 0 | D11: 0
A12: MEZZ7 | C12: 0 | D12: 0
A13: MEZZ8 | C13: 0 | D13: 0
A14: MEZZ9 | C14: 0 | D14: 0
A15: MEZZ10 | C15: 0 | D15: 0
A17: TOTAL | B17: Mezzanine Debt | C17: =SUM(C6:C15) | D17: Weighted Avg: | E17: =SUMPRODUCT(C6:C15,D6:D15)/C17
A20: INSTRUCTIONS:
A21: • Enter lender names in column B (yellow cells)
A22: • Enter loan amounts in column C (yellow cells)
A23: • Enter interest rates in column D (yellow cells)
A24: • Add any notes in column E
A25: • Total will update automatically
A26: • This total is linked to Sources & Uses - Construction
